[2015-07-03 21:26:51,677] WARNING : Not Found: /
[2015-07-03 21:39:38,336] WARNING : Not Found: /
[2015-07-03 21:39:38,411] WARNING : Not Found: /favicon.ico
[2015-07-03 21:39:40,707] WARNING : Not Found: /
[2015-07-06 10:11:43,075] WARNING : Not Found: /favicon.ico
[2015-07-06 21:27:13,726] WARNING : Not Found: /admin/blog/blogpost/
[2015-07-06 21:50:38,223] ERROR : Internal Server Error: /admin/logout/
Traceback (most recent call last):
  File "D:\Python27\lib\site-packages\django\core\handlers\base.py", line 114, in get_response
    response = wrapped_callback(request, *callback_args, **callback_kwargs)
  File "D:\Python27\lib\site-packages\django\contrib\admin\sites.py", line 215, in wrapper
    return self.admin_view(view, cacheable)(*args, **kwargs)
  File "D:\Python27\lib\site-packages\django\utils\decorators.py", line 99, in _wrapped_view
    response = view_func(request, *args, **kwargs)
  File "D:\Python27\lib\site-packages\django\views\decorators\cache.py", line 52, in _wrapped_view_func
    response = view_func(request, *args, **kwargs)
  File "D:\Python27\lib\site-packages\django\contrib\admin\sites.py", line 192, in inner
    if not self.has_permission(request):
  File "D:\Python27\lib\site-packages\django\contrib\admin\sites.py", line 143, in has_permission
    return request.user.is_active and request.user.is_staff
  File "D:\Python27\lib\site-packages\django\utils\functional.py", line 213, in inner
    self._setup()
  File "D:\Python27\lib\site-packages\django\utils\functional.py", line 298, in _setup
    self._wrapped = self._setupfunc()
  File "D:\Python27\lib\site-packages\django\contrib\auth\middleware.py", line 18, in <lambda>
    request.user = SimpleLazyObject(lambda: get_user(request))
  File "D:\Python27\lib\site-packages\django\contrib\auth\middleware.py", line 10, in get_user
    request._cached_user = auth.get_user(request)
  File "D:\Python27\lib\site-packages\django\contrib\auth\__init__.py", line 140, in get_user
    user_id = request.session[SESSION_KEY]
  File "D:\Python27\lib\site-packages\django\contrib\sessions\backends\base.py", line 47, in __getitem__
    return self._session[key]
  File "D:\Python27\lib\site-packages\django\contrib\sessions\backends\base.py", line 173, in _get_session
    self._session_cache = self.load()
  File "D:\Python27\lib\site-packages\django\contrib\sessions\backends\db.py", line 20, in load
    expire_date__gt=timezone.now()
  File "D:\Python27\lib\site-packages\django\db\models\manager.py", line 151, in get
    return self.get_queryset().get(*args, **kwargs)
  File "D:\Python27\lib\site-packages\django\db\models\query.py", line 301, in get
    num = len(clone)
  File "D:\Python27\lib\site-packages\django\db\models\query.py", line 77, in __len__
    self._fetch_all()
  File "D:\Python27\lib\site-packages\django\db\models\query.py", line 854, in _fetch_all
    self._result_cache = list(self.iterator())
  File "D:\Python27\lib\site-packages\django\db\models\query.py", line 220, in iterator
    for row in compiler.results_iter():
  File "D:\Python27\lib\site-packages\django\db\models\sql\compiler.py", line 713, in results_iter
    for rows in self.execute_sql(MULTI):
  File "D:\Python27\lib\site-packages\django\db\models\sql\compiler.py", line 786, in execute_sql
    cursor.execute(sql, params)
  File "D:\Python27\lib\site-packages\django\db\backends\util.py", line 69, in execute
    return super(CursorDebugWrapper, self).execute(sql, params)
  File "D:\Python27\lib\site-packages\django\db\backends\util.py", line 53, in execute
    return self.cursor.execute(sql, params)
  File "D:\Python27\lib\site-packages\django\db\utils.py", line 99, in __exit__
    six.reraise(dj_exc_type, dj_exc_value, traceback)
  File "D:\Python27\lib\site-packages\django\db\backends\util.py", line 53, in execute
    return self.cursor.execute(sql, params)
  File "D:\Python27\lib\site-packages\django\db\backends\mysql\base.py", line 124, in execute
    return self.cursor.execute(query, args)
  File "D:\Python27\lib\site-packages\MySQLdb\cursors.py", line 205, in execute
    self.errorhandler(self, exc, value)
  File "D:\Python27\lib\site-packages\MySQLdb\connections.py", line 36, in defaulterrorhandler
    raise errorclass, errorvalue
ProgrammingError: (1146, "Table 'mysitedb.django_session' doesn't exist")
[2015-07-06 21:50:46,963] ERROR : Internal Server Error: /admin/
Traceback (most recent call last):
  File "D:\Python27\lib\site-packages\django\core\handlers\base.py", line 114, in get_response
    response = wrapped_callback(request, *callback_args, **callback_kwargs)
  File "D:\Python27\lib\site-packages\django\contrib\admin\sites.py", line 215, in wrapper
    return self.admin_view(view, cacheable)(*args, **kwargs)
  File "D:\Python27\lib\site-packages\django\utils\decorators.py", line 99, in _wrapped_view
    response = view_func(request, *args, **kwargs)
  File "D:\Python27\lib\site-packages\django\views\decorators\cache.py", line 52, in _wrapped_view_func
    response = view_func(request, *args, **kwargs)
  File "D:\Python27\lib\site-packages\django\contrib\admin\sites.py", line 192, in inner
    if not self.has_permission(request):
  File "D:\Python27\lib\site-packages\django\contrib\admin\sites.py", line 143, in has_permission
    return request.user.is_active and request.user.is_staff
  File "D:\Python27\lib\site-packages\django\utils\functional.py", line 213, in inner
    self._setup()
  File "D:\Python27\lib\site-packages\django\utils\functional.py", line 298, in _setup
    self._wrapped = self._setupfunc()
  File "D:\Python27\lib\site-packages\django\contrib\auth\middleware.py", line 18, in <lambda>
    request.user = SimpleLazyObject(lambda: get_user(request))
  File "D:\Python27\lib\site-packages\django\contrib\auth\middleware.py", line 10, in get_user
    request._cached_user = auth.get_user(request)
  File "D:\Python27\lib\site-packages\django\contrib\auth\__init__.py", line 140, in get_user
    user_id = request.session[SESSION_KEY]
  File "D:\Python27\lib\site-packages\django\contrib\sessions\backends\base.py", line 47, in __getitem__
    return self._session[key]
  File "D:\Python27\lib\site-packages\django\contrib\sessions\backends\base.py", line 173, in _get_session
    self._session_cache = self.load()
  File "D:\Python27\lib\site-packages\django\contrib\sessions\backends\db.py", line 20, in load
    expire_date__gt=timezone.now()
  File "D:\Python27\lib\site-packages\django\db\models\manager.py", line 151, in get
    return self.get_queryset().get(*args, **kwargs)
  File "D:\Python27\lib\site-packages\django\db\models\query.py", line 301, in get
    num = len(clone)
  File "D:\Python27\lib\site-packages\django\db\models\query.py", line 77, in __len__
    self._fetch_all()
  File "D:\Python27\lib\site-packages\django\db\models\query.py", line 854, in _fetch_all
    self._result_cache = list(self.iterator())
  File "D:\Python27\lib\site-packages\django\db\models\query.py", line 220, in iterator
    for row in compiler.results_iter():
  File "D:\Python27\lib\site-packages\django\db\models\sql\compiler.py", line 713, in results_iter
    for rows in self.execute_sql(MULTI):
  File "D:\Python27\lib\site-packages\django\db\models\sql\compiler.py", line 786, in execute_sql
    cursor.execute(sql, params)
  File "D:\Python27\lib\site-packages\django\db\backends\util.py", line 69, in execute
    return super(CursorDebugWrapper, self).execute(sql, params)
  File "D:\Python27\lib\site-packages\django\db\backends\util.py", line 53, in execute
    return self.cursor.execute(sql, params)
  File "D:\Python27\lib\site-packages\django\db\utils.py", line 99, in __exit__
    six.reraise(dj_exc_type, dj_exc_value, traceback)
  File "D:\Python27\lib\site-packages\django\db\backends\util.py", line 53, in execute
    return self.cursor.execute(sql, params)
  File "D:\Python27\lib\site-packages\django\db\backends\mysql\base.py", line 124, in execute
    return self.cursor.execute(query, args)
  File "D:\Python27\lib\site-packages\MySQLdb\cursors.py", line 205, in execute
    self.errorhandler(self, exc, value)
  File "D:\Python27\lib\site-packages\MySQLdb\connections.py", line 36, in defaulterrorhandler
    raise errorclass, errorvalue
ProgrammingError: (1146, "Table 'mysitedb.django_session' doesn't exist")
[2015-07-06 22:07:42,092] WARNING : Not Found: /admin/gallery/item/1/photos/538c6f95jw1er335gl39lj20sg0g0dih.jpg/
[2015-07-06 22:08:04,167] WARNING : Not Found: /admin/gallery/item/1/photos/222.PNG/
[2015-07-06 22:08:57,539] WARNING : Not Found: /admin/gallery/item/1/photos/538c6f95jw1er335gl39lj20sg0g0dih.jpg/
[2015-07-06 22:13:14,357] WARNING : Not Found: /media/photos/538c6f95jw1er335gl39lj20sg0g0dih.jpg
[2015-07-06 22:14:17,246] WARNING : Not Found: /media/photos/538c6f95jw1er335gl39lj20sg0g0dih.jpg
[2015-07-06 22:24:20,144] WARNING : Not Found: /media/photos/222.PNG
[2015-07-06 22:24:31,589] ERROR : Internal Server Error: /admin/gallery/item/1/
Traceback (most recent call last):
  File "D:\Python27\lib\site-packages\django\core\handlers\base.py", line 101, in get_response
    resolver_match = resolver.resolve(request.path_info)
  File "D:\Python27\lib\site-packages\django\core\urlresolvers.py", line 337, in resolve
    for pattern in self.url_patterns:
  File "D:\Python27\lib\site-packages\django\core\urlresolvers.py", line 365, in url_patterns
    patterns = getattr(self.urlconf_module, "urlpatterns", self.urlconf_module)
  File "D:\Python27\lib\site-packages\django\core\urlresolvers.py", line 360, in urlconf_module
    self._urlconf_module = import_module(self.urlconf_name)
  File "D:\Python27\lib\site-packages\django\utils\importlib.py", line 40, in import_module
    __import__(name)
  File "D:\workspace\mysite\mysite\urls.py", line 24, in <module>
    )+static(settings.MEDIA_URLL,document_root=settings.MEDIA_ROOT)
  File "D:\Python27\lib\site-packages\django\conf\__init__.py", line 55, in __getattr__
    return getattr(self._wrapped, name)
AttributeError: 'Settings' object has no attribute 'MEDIA_URLL'
[2015-07-06 22:24:38,677] ERROR : Internal Server Error: /admi
Traceback (most recent call last):
  File "D:\Python27\lib\site-packages\django\core\handlers\base.py", line 90, in get_response
    response = middleware_method(request)
  File "D:\Python27\lib\site-packages\django\middleware\common.py", line 71, in process_request
    if (not urlresolvers.is_valid_path(request.path_info, urlconf) and
  File "D:\Python27\lib\site-packages\django\core\urlresolvers.py", line 596, in is_valid_path
    resolve(path, urlconf)
  File "D:\Python27\lib\site-packages\django\core\urlresolvers.py", line 476, in resolve
    return get_resolver(urlconf).resolve(path)
  File "D:\Python27\lib\site-packages\django\core\urlresolvers.py", line 337, in resolve
    for pattern in self.url_patterns:
  File "D:\Python27\lib\site-packages\django\core\urlresolvers.py", line 365, in url_patterns
    patterns = getattr(self.urlconf_module, "urlpatterns", self.urlconf_module)
  File "D:\Python27\lib\site-packages\django\core\urlresolvers.py", line 360, in urlconf_module
    self._urlconf_module = import_module(self.urlconf_name)
  File "D:\Python27\lib\site-packages\django\utils\importlib.py", line 40, in import_module
    __import__(name)
  File "D:\workspace\mysite\mysite\urls.py", line 24, in <module>
    )+static(settings.MEDIA_URLL,document_root=settings.MEDIA_ROOT)
  File "D:\Python27\lib\site-packages\django\conf\__init__.py", line 55, in __getattr__
    return getattr(self._wrapped, name)
AttributeError: 'Settings' object has no attribute 'MEDIA_URLL'
[2015-07-06 22:24:47,341] WARNING : Not Found: /admi
[2015-07-07 09:42:56,075] WARNING : Not Found: /favicon.ico
[2015-07-09 18:39:20,898] ERROR : Internal Server Error: /
Traceback (most recent call last):
  File "D:\Python27\lib\site-packages\django\core\handlers\base.py", line 101, in get_response
    resolver_match = resolver.resolve(request.path_info)
  File "D:\Python27\lib\site-packages\django\core\urlresolvers.py", line 337, in resolve
    for pattern in self.url_patterns:
  File "D:\Python27\lib\site-packages\django\core\urlresolvers.py", line 365, in url_patterns
    patterns = getattr(self.urlconf_module, "urlpatterns", self.urlconf_module)
  File "D:\Python27\lib\site-packages\django\core\urlresolvers.py", line 360, in urlconf_module
    self._urlconf_module = import_module(self.urlconf_name)
  File "D:\Python27\lib\site-packages\django\utils\importlib.py", line 40, in import_module
    __import__(name)
  File "D:\workspace\mysite\mysite\urls.py", line 24, in <module>
    url(r'^depotapp/$',include('apps.depotapp.urls')),
  File "D:\Python27\lib\site-packages\django\conf\urls\__init__.py", line 26, in include
    urlconf_module = import_module(urlconf_module)
  File "D:\Python27\lib\site-packages\django\utils\importlib.py", line 40, in import_module
    __import__(name)
  File "D:\workspace\mysite\apps\depotapp\urls.py", line 3, in <module>
    import views
  File "D:\workspace\mysite\apps\depotapp\views.py", line 6, in <module>
    from forms import ProductForm
  File "D:\workspace\mysite\apps\depotapp\forms.py", line 3, in <module>
    class ProductForm(forms.Form):
  File "D:\workspace\mysite\apps\depotapp\forms.py", line 5, in ProductForm
    description=forms.TextField()
AttributeError: 'module' object has no attribute 'TextField'
[2015-07-09 18:40:05,848] ERROR : Internal Server Error: /depotapp/product/create
Traceback (most recent call last):
  File "D:\Python27\lib\site-packages\django\core\handlers\base.py", line 90, in get_response
    response = middleware_method(request)
  File "D:\Python27\lib\site-packages\django\middleware\common.py", line 71, in process_request
    if (not urlresolvers.is_valid_path(request.path_info, urlconf) and
  File "D:\Python27\lib\site-packages\django\core\urlresolvers.py", line 596, in is_valid_path
    resolve(path, urlconf)
  File "D:\Python27\lib\site-packages\django\core\urlresolvers.py", line 476, in resolve
    return get_resolver(urlconf).resolve(path)
  File "D:\Python27\lib\site-packages\django\core\urlresolvers.py", line 337, in resolve
    for pattern in self.url_patterns:
  File "D:\Python27\lib\site-packages\django\core\urlresolvers.py", line 365, in url_patterns
    patterns = getattr(self.urlconf_module, "urlpatterns", self.urlconf_module)
  File "D:\Python27\lib\site-packages\django\core\urlresolvers.py", line 360, in urlconf_module
    self._urlconf_module = import_module(self.urlconf_name)
  File "D:\Python27\lib\site-packages\django\utils\importlib.py", line 40, in import_module
    __import__(name)
  File "D:\workspace\mysite\mysite\urls.py", line 24, in <module>
    url(r'^depotapp/$',include('apps.depotapp.urls')),
  File "D:\Python27\lib\site-packages\django\conf\urls\__init__.py", line 26, in include
    urlconf_module = import_module(urlconf_module)
  File "D:\Python27\lib\site-packages\django\utils\importlib.py", line 40, in import_module
    __import__(name)
  File "D:\workspace\mysite\apps\depotapp\urls.py", line 3, in <module>
    import views
  File "D:\workspace\mysite\apps\depotapp\views.py", line 6, in <module>
    from forms import ProductForm
  File "D:\workspace\mysite\apps\depotapp\forms.py", line 3, in <module>
    class ProductForm(forms.Form):
  File "D:\workspace\mysite\apps\depotapp\forms.py", line 5, in ProductForm
    description=forms.TextField()
AttributeError: 'module' object has no attribute 'TextField'
[2015-07-09 18:47:20,506] WARNING : Not Found: /depotapp/product/create
[2015-07-09 18:47:43,427] WARNING : Not Found: /depotapp/product/create
[2015-07-09 18:48:45,940] WARNING : Not Found: /depotapp/product/create
[2015-07-09 18:59:22,525] WARNING : Not Found: /depotapp/product/create/
[2015-07-09 18:59:24,802] WARNING : Not Found: /depotapp/product/create/
[2015-07-09 18:59:26,306] WARNING : Not Found: /depotapp/product/create/
[2015-07-09 20:07:19,917] ERROR : Internal Server Error: /depotapp/
Traceback (most recent call last):
  File "D:\Python27\lib\site-packages\django\core\handlers\base.py", line 114, in get_response
    response = wrapped_callback(request, *callback_args, **callback_kwargs)
  File "D:\workspace\mysite\apps\depotapp\views.py", line 12, in index
    return render_to_response()
  File "D:\Python27\lib\site-packages\django\shortcuts\__init__.py", line 29, in render_to_response
    return HttpResponse(loader.render_to_string(*args, **kwargs), **httpresponse_kwargs)
TypeError: render_to_string() takes at least 1 argument (0 given)
[2015-07-09 20:09:16,552] WARNING : Not Found: /depotapp/product/create/
[2015-07-09 20:10:54,854] WARNING : Not Found: /depotapp/product/create/
[2015-07-09 20:23:44,507] WARNING : Not Found: /depotapp/
[2015-07-09 20:23:46,483] WARNING : Not Found: /depotapp/
[2015-07-09 20:23:58,492] WARNING : Not Found: /depotapp/
[2015-07-09 20:24:00,428] WARNING : Not Found: /depotapp/
[2015-07-09 20:24:00,618] WARNING : Not Found: /depotapp/
[2015-07-09 20:24:01,158] WARNING : Not Found: /depotapp/
[2015-07-09 20:24:01,200] WARNING : Not Found: /depotapp/
[2015-07-09 20:24:01,234] WARNING : Not Found: /depotapp/
[2015-07-09 20:24:01,276] WARNING : Not Found: /depotapp/
[2015-07-09 20:24:01,311] WARNING : Not Found: /depotapp/
[2015-07-09 20:24:01,344] WARNING : Not Found: /depotapp/
[2015-07-09 20:24:01,381] WARNING : Not Found: /depotapp/
[2015-07-09 20:24:01,414] WARNING : Not Found: /depotapp/
[2015-07-09 20:24:01,457] WARNING : Not Found: /depotapp/
[2015-07-09 20:24:01,496] WARNING : Not Found: /depotapp/
[2015-07-09 20:24:01,532] WARNING : Not Found: /depotapp/
[2015-07-09 20:24:01,569] WARNING : Not Found: /depotapp/
[2015-07-09 20:24:12,453] WARNING : Not Found: /depotapp
[2015-07-09 20:25:40,813] WARNING : Not Found: /depotapp/
[2015-07-09 20:25:53,953] WARNING : Not Found: /depotapp/
[2015-07-09 20:25:57,828] WARNING : Not Found: /depotapp/
[2015-07-09 20:25:59,602] WARNING : Not Found: /depotapp/
[2015-07-09 20:33:51,336] WARNING : Not Found: /depotapp/index/
[2015-07-14 15:30:40,888] WARNING : Not Found: /favicon.ico
[2015-07-20 11:13:30,562] WARNING : Not Found: /favicon.ico
[2015-07-20 19:03:02,565] WARNING : Not Found: /depotapp/
[2015-07-20 19:11:02,111] WARNING : Not Found: /depotapp/
[2015-07-20 21:36:30,667] ERROR : Internal Server Error: /depotapp/api/cart/items
Traceback (most recent call last):
  File "D:\Python27\lib\site-packages\django\core\handlers\base.py", line 90, in get_response
    response = middleware_method(request)
  File "D:\Python27\lib\site-packages\django\middleware\common.py", line 71, in process_request
    if (not urlresolvers.is_valid_path(request.path_info, urlconf) and
  File "D:\Python27\lib\site-packages\django\core\urlresolvers.py", line 596, in is_valid_path
    resolve(path, urlconf)
  File "D:\Python27\lib\site-packages\django\core\urlresolvers.py", line 476, in resolve
    return get_resolver(urlconf).resolve(path)
  File "D:\Python27\lib\site-packages\django\core\urlresolvers.py", line 337, in resolve
    for pattern in self.url_patterns:
  File "D:\Python27\lib\site-packages\django\core\urlresolvers.py", line 365, in url_patterns
    patterns = getattr(self.urlconf_module, "urlpatterns", self.urlconf_module)
  File "D:\Python27\lib\site-packages\django\core\urlresolvers.py", line 360, in urlconf_module
    self._urlconf_module = import_module(self.urlconf_name)
  File "D:\Python27\lib\site-packages\django\utils\importlib.py", line 40, in import_module
    __import__(name)
  File "D:\workspace\mysite\mysite\urls.py", line 24, in <module>
    url(r'^depotapp/',include('apps.depotapp.urls')),
  File "D:\Python27\lib\site-packages\django\conf\urls\__init__.py", line 26, in include
    urlconf_module = import_module(urlconf_module)
  File "D:\Python27\lib\site-packages\django\utils\importlib.py", line 40, in import_module
    __import__(name)
  File "D:\workspace\mysite\apps\depotapp\urls.py", line 16, in <module>
    url(r'^api/cart/items',)
TypeError: url() takes at least 2 arguments (1 given)
[2015-07-20 21:36:49,753] ERROR : Internal Server Error: /depotapp/api/cart/items
Traceback (most recent call last):
  File "D:\Python27\lib\site-packages\django\core\handlers\base.py", line 114, in get_response
    response = wrapped_callback(request, *callback_args, **callback_kwargs)
  File "D:\Python27\lib\site-packages\django\views\decorators\csrf.py", line 57, in wrapped_view
    return view_func(*args, **kwargs)
  File "D:\Python27\lib\site-packages\django\views\generic\base.py", line 69, in view
    return self.dispatch(request, *args, **kwargs)
  File "D:\Python27\lib\site-packages\rest_framework\views.py", line 456, in dispatch
    response = self.handle_exception(exc)
  File "D:\Python27\lib\site-packages\rest_framework\views.py", line 453, in dispatch
    response = handler(request, *args, **kwargs)
  File "D:\Python27\lib\site-packages\rest_framework\decorators.py", line 50, in handler
    return func(*args, **kwargs)
  File "D:\workspace\mysite\apps\depotapp\views.py", line 102, in cart_item_list
    return JSONResponse(serializer.data)
  File "D:\Python27\lib\site-packages\rest_framework\serializers.py", line 470, in data
    ret = super(Serializer, self).data
  File "D:\Python27\lib\site-packages\rest_framework\serializers.py", line 217, in data
    self._data = self.to_representation(self.instance)
  File "D:\Python27\lib\site-packages\rest_framework\serializers.py", line 430, in to_representation
    attribute = field.get_attribute(instance)
  File "D:\Python27\lib\site-packages\rest_framework\fields.py", line 317, in get_attribute
    raise type(exc)(msg)
AttributeError: Got AttributeError when attempting to get a value for field `unit_price` on serializer `LineItemSerializer`.
The serializer field might be named incorrectly and not match any attribute or key on the `ModelBase` instance.
Original exception text was: type object 'LineItem' has no attribute 'unit_price'.
[2015-07-20 21:37:32,099] ERROR : Internal Server Error: /depotapp/api/cart/items
Traceback (most recent call last):
  File "D:\Python27\lib\site-packages\django\core\handlers\base.py", line 114, in get_response
    response = wrapped_callback(request, *callback_args, **callback_kwargs)
  File "D:\Python27\lib\site-packages\django\views\decorators\csrf.py", line 57, in wrapped_view
    return view_func(*args, **kwargs)
  File "D:\Python27\lib\site-packages\django\views\generic\base.py", line 69, in view
    return self.dispatch(request, *args, **kwargs)
  File "D:\Python27\lib\site-packages\rest_framework\views.py", line 456, in dispatch
    response = self.handle_exception(exc)
  File "D:\Python27\lib\site-packages\rest_framework\views.py", line 453, in dispatch
    response = handler(request, *args, **kwargs)
  File "D:\Python27\lib\site-packages\rest_framework\decorators.py", line 50, in handler
    return func(*args, **kwargs)
  File "D:\workspace\mysite\apps\depotapp\views.py", line 102, in cart_item_list
    return JSONResponse(serializer.data)
  File "D:\Python27\lib\site-packages\rest_framework\serializers.py", line 470, in data
    ret = super(Serializer, self).data
  File "D:\Python27\lib\site-packages\rest_framework\serializers.py", line 217, in data
    self._data = self.to_representation(self.instance)
  File "D:\Python27\lib\site-packages\rest_framework\serializers.py", line 430, in to_representation
    attribute = field.get_attribute(instance)
  File "D:\Python27\lib\site-packages\rest_framework\fields.py", line 317, in get_attribute
    raise type(exc)(msg)
AttributeError: Got AttributeError when attempting to get a value for field `unit_price` on serializer `LineItemSerializer`.
The serializer field might be named incorrectly and not match any attribute or key on the `ModelBase` instance.
Original exception text was: type object 'LineItem' has no attribute 'unit_price'.
[2015-07-20 21:39:10,295] ERROR : Internal Server Error: /depotapp/api/cart/items
Traceback (most recent call last):
  File "D:\Python27\lib\site-packages\django\core\handlers\base.py", line 114, in get_response
    response = wrapped_callback(request, *callback_args, **callback_kwargs)
  File "D:\Python27\lib\site-packages\django\views\decorators\csrf.py", line 57, in wrapped_view
    return view_func(*args, **kwargs)
  File "D:\Python27\lib\site-packages\django\views\generic\base.py", line 69, in view
    return self.dispatch(request, *args, **kwargs)
  File "D:\Python27\lib\site-packages\rest_framework\views.py", line 456, in dispatch
    response = self.handle_exception(exc)
  File "D:\Python27\lib\site-packages\rest_framework\views.py", line 453, in dispatch
    response = handler(request, *args, **kwargs)
  File "D:\Python27\lib\site-packages\rest_framework\decorators.py", line 50, in handler
    return func(*args, **kwargs)
  File "D:\workspace\mysite\apps\depotapp\views.py", line 102, in cart_item_list
    return JSONResponse(serializer.data)
  File "D:\Python27\lib\site-packages\rest_framework\serializers.py", line 470, in data
    ret = super(Serializer, self).data
  File "D:\Python27\lib\site-packages\rest_framework\serializers.py", line 217, in data
    self._data = self.to_representation(self.instance)
  File "D:\Python27\lib\site-packages\rest_framework\serializers.py", line 430, in to_representation
    attribute = field.get_attribute(instance)
  File "D:\Python27\lib\site-packages\rest_framework\fields.py", line 317, in get_attribute
    raise type(exc)(msg)
AttributeError: Got AttributeError when attempting to get a value for field `unit_price` on serializer `LineItemSerializer`.
The serializer field might be named incorrectly and not match any attribute or key on the `ModelBase` instance.
Original exception text was: type object 'LineItem' has no attribute 'unit_price'.
[2015-07-20 21:45:30,585] ERROR : Internal Server Error: /depotapp/api/cart/items
Traceback (most recent call last):
  File "D:\Python27\lib\site-packages\django\core\handlers\base.py", line 114, in get_response
    response = wrapped_callback(request, *callback_args, **callback_kwargs)
  File "D:\Python27\lib\site-packages\django\views\decorators\csrf.py", line 57, in wrapped_view
    return view_func(*args, **kwargs)
  File "D:\Python27\lib\site-packages\django\views\generic\base.py", line 69, in view
    return self.dispatch(request, *args, **kwargs)
  File "D:\Python27\lib\site-packages\rest_framework\views.py", line 456, in dispatch
    response = self.handle_exception(exc)
  File "D:\Python27\lib\site-packages\rest_framework\views.py", line 453, in dispatch
    response = handler(request, *args, **kwargs)
  File "D:\Python27\lib\site-packages\rest_framework\decorators.py", line 50, in handler
    return func(*args, **kwargs)
  File "D:\workspace\mysite\apps\depotapp\views.py", line 102, in cart_item_list
    return JSONResponse(serializer.data)
  File "D:\Python27\lib\site-packages\rest_framework\serializers.py", line 470, in data
    ret = super(Serializer, self).data
  File "D:\Python27\lib\site-packages\rest_framework\serializers.py", line 217, in data
    self._data = self.to_representation(self.instance)
  File "D:\Python27\lib\site-packages\rest_framework\serializers.py", line 430, in to_representation
    attribute = field.get_attribute(instance)
  File "D:\Python27\lib\site-packages\rest_framework\fields.py", line 317, in get_attribute
    raise type(exc)(msg)
AttributeError: Got AttributeError when attempting to get a value for field `unit_price` on serializer `LineItemSerializer`.
The serializer field might be named incorrectly and not match any attribute or key on the `ModelBase` instance.
Original exception text was: type object 'LineItem' has no attribute 'unit_price'.
[2015-07-20 21:45:51,974] ERROR : Internal Server Error: /depotapp/api/cart/items
Traceback (most recent call last):
  File "D:\Python27\lib\site-packages\django\core\handlers\base.py", line 114, in get_response
    response = wrapped_callback(request, *callback_args, **callback_kwargs)
  File "D:\Python27\lib\site-packages\django\views\decorators\csrf.py", line 57, in wrapped_view
    return view_func(*args, **kwargs)
  File "D:\Python27\lib\site-packages\django\views\generic\base.py", line 69, in view
    return self.dispatch(request, *args, **kwargs)
  File "D:\Python27\lib\site-packages\rest_framework\views.py", line 456, in dispatch
    response = self.handle_exception(exc)
  File "D:\Python27\lib\site-packages\rest_framework\views.py", line 453, in dispatch
    response = handler(request, *args, **kwargs)
  File "D:\Python27\lib\site-packages\rest_framework\decorators.py", line 50, in handler
    return func(*args, **kwargs)
  File "D:\workspace\mysite\apps\depotapp\views.py", line 102, in cart_item_list
    return JSONResponse(serializer.data)
  File "D:\Python27\lib\site-packages\rest_framework\serializers.py", line 470, in data
    ret = super(Serializer, self).data
  File "D:\Python27\lib\site-packages\rest_framework\serializers.py", line 217, in data
    self._data = self.to_representation(self.instance)
  File "D:\Python27\lib\site-packages\rest_framework\serializers.py", line 430, in to_representation
    attribute = field.get_attribute(instance)
  File "D:\Python27\lib\site-packages\rest_framework\fields.py", line 317, in get_attribute
    raise type(exc)(msg)
AttributeError: Got AttributeError when attempting to get a value for field `unit_price` on serializer `LineItemSerializer`.
The serializer field might be named incorrectly and not match any attribute or key on the `ModelBase` instance.
Original exception text was: type object 'LineItem' has no attribute 'unit_price'.
[2015-07-20 21:45:53,263] ERROR : Internal Server Error: /depotapp/api/cart/items
Traceback (most recent call last):
  File "D:\Python27\lib\site-packages\django\core\handlers\base.py", line 114, in get_response
    response = wrapped_callback(request, *callback_args, **callback_kwargs)
  File "D:\Python27\lib\site-packages\django\views\decorators\csrf.py", line 57, in wrapped_view
    return view_func(*args, **kwargs)
  File "D:\Python27\lib\site-packages\django\views\generic\base.py", line 69, in view
    return self.dispatch(request, *args, **kwargs)
  File "D:\Python27\lib\site-packages\rest_framework\views.py", line 456, in dispatch
    response = self.handle_exception(exc)
  File "D:\Python27\lib\site-packages\rest_framework\views.py", line 453, in dispatch
    response = handler(request, *args, **kwargs)
  File "D:\Python27\lib\site-packages\rest_framework\decorators.py", line 50, in handler
    return func(*args, **kwargs)
  File "D:\workspace\mysite\apps\depotapp\views.py", line 102, in cart_item_list
    return JSONResponse(serializer.data)
  File "D:\Python27\lib\site-packages\rest_framework\serializers.py", line 470, in data
    ret = super(Serializer, self).data
  File "D:\Python27\lib\site-packages\rest_framework\serializers.py", line 217, in data
    self._data = self.to_representation(self.instance)
  File "D:\Python27\lib\site-packages\rest_framework\serializers.py", line 430, in to_representation
    attribute = field.get_attribute(instance)
  File "D:\Python27\lib\site-packages\rest_framework\fields.py", line 317, in get_attribute
    raise type(exc)(msg)
AttributeError: Got AttributeError when attempting to get a value for field `unit_price` on serializer `LineItemSerializer`.
The serializer field might be named incorrectly and not match any attribute or key on the `ModelBase` instance.
Original exception text was: type object 'LineItem' has no attribute 'unit_price'.
[2015-07-20 21:51:57,773] ERROR : Internal Server Error: /depotapp/api/cart/items
Traceback (most recent call last):
  File "D:\Python27\lib\site-packages\django\core\handlers\base.py", line 114, in get_response
    response = wrapped_callback(request, *callback_args, **callback_kwargs)
  File "D:\Python27\lib\site-packages\django\views\decorators\csrf.py", line 57, in wrapped_view
    return view_func(*args, **kwargs)
  File "D:\Python27\lib\site-packages\django\views\generic\base.py", line 69, in view
    return self.dispatch(request, *args, **kwargs)
  File "D:\Python27\lib\site-packages\rest_framework\views.py", line 456, in dispatch
    response = self.handle_exception(exc)
  File "D:\Python27\lib\site-packages\rest_framework\views.py", line 453, in dispatch
    response = handler(request, *args, **kwargs)
  File "D:\Python27\lib\site-packages\rest_framework\decorators.py", line 50, in handler
    return func(*args, **kwargs)
  File "D:\workspace\mysite\apps\depotapp\views.py", line 102, in cart_item_list
    return JSONResponse(serializer.data)
  File "D:\Python27\lib\site-packages\rest_framework\serializers.py", line 470, in data
    ret = super(Serializer, self).data
  File "D:\Python27\lib\site-packages\rest_framework\serializers.py", line 217, in data
    self._data = self.to_representation(self.instance)
  File "D:\Python27\lib\site-packages\rest_framework\serializers.py", line 430, in to_representation
    attribute = field.get_attribute(instance)
  File "D:\Python27\lib\site-packages\rest_framework\fields.py", line 317, in get_attribute
    raise type(exc)(msg)
AttributeError: Got AttributeError when attempting to get a value for field `unit_price` on serializer `LineItemSerializer`.
The serializer field might be named incorrectly and not match any attribute or key on the `ModelBase` instance.
Original exception text was: type object 'LineItem' has no attribute 'unit_price'.
[2015-07-20 22:01:32,372] ERROR : Internal Server Error: /depotapp/api/cart/items
Traceback (most recent call last):
  File "D:\Python27\lib\site-packages\django\core\handlers\base.py", line 114, in get_response
    response = wrapped_callback(request, *callback_args, **callback_kwargs)
  File "D:\Python27\lib\site-packages\django\views\decorators\csrf.py", line 57, in wrapped_view
    return view_func(*args, **kwargs)
  File "D:\Python27\lib\site-packages\django\views\generic\base.py", line 69, in view
    return self.dispatch(request, *args, **kwargs)
  File "D:\Python27\lib\site-packages\rest_framework\views.py", line 456, in dispatch
    response = self.handle_exception(exc)
  File "D:\Python27\lib\site-packages\rest_framework\views.py", line 453, in dispatch
    response = handler(request, *args, **kwargs)
  File "D:\Python27\lib\site-packages\rest_framework\decorators.py", line 50, in handler
    return func(*args, **kwargs)
  File "D:\workspace\mysite\apps\depotapp\views.py", line 102, in cart_item_list
    return JSONResponse(serializer.data)
  File "D:\Python27\lib\site-packages\rest_framework\serializers.py", line 470, in data
    ret = super(Serializer, self).data
  File "D:\Python27\lib\site-packages\rest_framework\serializers.py", line 217, in data
    self._data = self.to_representation(self.instance)
  File "D:\Python27\lib\site-packages\rest_framework\serializers.py", line 430, in to_representation
    attribute = field.get_attribute(instance)
  File "D:\Python27\lib\site-packages\rest_framework\fields.py", line 317, in get_attribute
    raise type(exc)(msg)
AttributeError: Got AttributeError when attempting to get a value for field `unit_price` on serializer `LineItemSerializer`.
The serializer field might be named incorrectly and not match any attribute or key on the `ModelBase` instance.
Original exception text was: type object 'LineItem' has no attribute 'unit_price'.
[2015-07-20 22:01:33,607] ERROR : Internal Server Error: /depotapp/api/cart/items
Traceback (most recent call last):
  File "D:\Python27\lib\site-packages\django\core\handlers\base.py", line 114, in get_response
    response = wrapped_callback(request, *callback_args, **callback_kwargs)
  File "D:\Python27\lib\site-packages\django\views\decorators\csrf.py", line 57, in wrapped_view
    return view_func(*args, **kwargs)
  File "D:\Python27\lib\site-packages\django\views\generic\base.py", line 69, in view
    return self.dispatch(request, *args, **kwargs)
  File "D:\Python27\lib\site-packages\rest_framework\views.py", line 456, in dispatch
    response = self.handle_exception(exc)
  File "D:\Python27\lib\site-packages\rest_framework\views.py", line 453, in dispatch
    response = handler(request, *args, **kwargs)
  File "D:\Python27\lib\site-packages\rest_framework\decorators.py", line 50, in handler
    return func(*args, **kwargs)
  File "D:\workspace\mysite\apps\depotapp\views.py", line 102, in cart_item_list
    return JSONResponse(serializer.data)
  File "D:\Python27\lib\site-packages\rest_framework\serializers.py", line 470, in data
    ret = super(Serializer, self).data
  File "D:\Python27\lib\site-packages\rest_framework\serializers.py", line 217, in data
    self._data = self.to_representation(self.instance)
  File "D:\Python27\lib\site-packages\rest_framework\serializers.py", line 430, in to_representation
    attribute = field.get_attribute(instance)
  File "D:\Python27\lib\site-packages\rest_framework\fields.py", line 317, in get_attribute
    raise type(exc)(msg)
AttributeError: Got AttributeError when attempting to get a value for field `unit_price` on serializer `LineItemSerializer`.
The serializer field might be named incorrectly and not match any attribute or key on the `ModelBase` instance.
Original exception text was: type object 'LineItem' has no attribute 'unit_price'.
[2015-07-20 22:02:32,210] ERROR : Internal Server Error: /depotapp/api/cart/items
Traceback (most recent call last):
  File "D:\Python27\lib\site-packages\django\core\handlers\base.py", line 114, in get_response
    response = wrapped_callback(request, *callback_args, **callback_kwargs)
  File "D:\Python27\lib\site-packages\django\views\decorators\csrf.py", line 57, in wrapped_view
    return view_func(*args, **kwargs)
  File "D:\Python27\lib\site-packages\django\views\generic\base.py", line 69, in view
    return self.dispatch(request, *args, **kwargs)
  File "D:\Python27\lib\site-packages\rest_framework\views.py", line 456, in dispatch
    response = self.handle_exception(exc)
  File "D:\Python27\lib\site-packages\rest_framework\views.py", line 453, in dispatch
    response = handler(request, *args, **kwargs)
  File "D:\Python27\lib\site-packages\rest_framework\decorators.py", line 50, in handler
    return func(*args, **kwargs)
  File "D:\workspace\mysite\apps\depotapp\views.py", line 102, in cart_item_list
    return JSONResponse(serializer.data)
  File "D:\Python27\lib\site-packages\rest_framework\serializers.py", line 622, in data
    ret = super(ListSerializer, self).data
  File "D:\Python27\lib\site-packages\rest_framework\serializers.py", line 217, in data
    self._data = self.to_representation(self.instance)
  File "D:\Python27\lib\site-packages\rest_framework\serializers.py", line 572, in to_representation
    self.child.to_representation(item) for item in iterable
TypeError: 'ModelBase' object is not iterable
[2015-07-20 22:02:34,342] ERROR : Internal Server Error: /depotapp/api/cart/items
Traceback (most recent call last):
  File "D:\Python27\lib\site-packages\django\core\handlers\base.py", line 114, in get_response
    response = wrapped_callback(request, *callback_args, **callback_kwargs)
  File "D:\Python27\lib\site-packages\django\views\decorators\csrf.py", line 57, in wrapped_view
    return view_func(*args, **kwargs)
  File "D:\Python27\lib\site-packages\django\views\generic\base.py", line 69, in view
    return self.dispatch(request, *args, **kwargs)
  File "D:\Python27\lib\site-packages\rest_framework\views.py", line 456, in dispatch
    response = self.handle_exception(exc)
  File "D:\Python27\lib\site-packages\rest_framework\views.py", line 453, in dispatch
    response = handler(request, *args, **kwargs)
  File "D:\Python27\lib\site-packages\rest_framework\decorators.py", line 50, in handler
    return func(*args, **kwargs)
  File "D:\workspace\mysite\apps\depotapp\views.py", line 102, in cart_item_list
    return JSONResponse(serializer.data)
  File "D:\Python27\lib\site-packages\rest_framework\serializers.py", line 622, in data
    ret = super(ListSerializer, self).data
  File "D:\Python27\lib\site-packages\rest_framework\serializers.py", line 217, in data
    self._data = self.to_representation(self.instance)
  File "D:\Python27\lib\site-packages\rest_framework\serializers.py", line 572, in to_representation
    self.child.to_representation(item) for item in iterable
TypeError: 'ModelBase' object is not iterable
[2015-07-20 22:02:35,604] ERROR : Internal Server Error: /depotapp/api/cart/items
Traceback (most recent call last):
  File "D:\Python27\lib\site-packages\django\core\handlers\base.py", line 114, in get_response
    response = wrapped_callback(request, *callback_args, **callback_kwargs)
  File "D:\Python27\lib\site-packages\django\views\decorators\csrf.py", line 57, in wrapped_view
    return view_func(*args, **kwargs)
  File "D:\Python27\lib\site-packages\django\views\generic\base.py", line 69, in view
    return self.dispatch(request, *args, **kwargs)
  File "D:\Python27\lib\site-packages\rest_framework\views.py", line 456, in dispatch
    response = self.handle_exception(exc)
  File "D:\Python27\lib\site-packages\rest_framework\views.py", line 453, in dispatch
    response = handler(request, *args, **kwargs)
  File "D:\Python27\lib\site-packages\rest_framework\decorators.py", line 50, in handler
    return func(*args, **kwargs)
  File "D:\workspace\mysite\apps\depotapp\views.py", line 102, in cart_item_list
    return JSONResponse(serializer.data)
  File "D:\Python27\lib\site-packages\rest_framework\serializers.py", line 622, in data
    ret = super(ListSerializer, self).data
  File "D:\Python27\lib\site-packages\rest_framework\serializers.py", line 217, in data
    self._data = self.to_representation(self.instance)
  File "D:\Python27\lib\site-packages\rest_framework\serializers.py", line 572, in to_representation
    self.child.to_representation(item) for item in iterable
TypeError: 'ModelBase' object is not iterable
[2015-07-20 22:07:21,894] ERROR : Internal Server Error: /depotapp/api/cart/items
Traceback (most recent call last):
  File "D:\Python27\lib\site-packages\django\core\handlers\base.py", line 114, in get_response
    response = wrapped_callback(request, *callback_args, **callback_kwargs)
  File "D:\Python27\lib\site-packages\django\views\decorators\csrf.py", line 57, in wrapped_view
    return view_func(*args, **kwargs)
  File "D:\Python27\lib\site-packages\django\views\generic\base.py", line 69, in view
    return self.dispatch(request, *args, **kwargs)
  File "D:\Python27\lib\site-packages\rest_framework\views.py", line 456, in dispatch
    response = self.handle_exception(exc)
  File "D:\Python27\lib\site-packages\rest_framework\views.py", line 453, in dispatch
    response = handler(request, *args, **kwargs)
  File "D:\Python27\lib\site-packages\rest_framework\decorators.py", line 50, in handler
    return func(*args, **kwargs)
  File "D:\workspace\mysite\apps\depotapp\views.py", line 98, in cart_item_list
    lineitem=LineItem.objects.get(id=id)
  File "D:\Python27\lib\site-packages\django\db\models\manager.py", line 151, in get
    return self.get_queryset().get(*args, **kwargs)
  File "D:\Python27\lib\site-packages\django\db\models\query.py", line 298, in get
    clone = self.filter(*args, **kwargs)
  File "D:\Python27\lib\site-packages\django\db\models\query.py", line 590, in filter
    return self._filter_or_exclude(False, *args, **kwargs)
  File "D:\Python27\lib\site-packages\django\db\models\query.py", line 608, in _filter_or_exclude
    clone.query.add_q(Q(*args, **kwargs))
  File "D:\Python27\lib\site-packages\django\db\models\sql\query.py", line 1198, in add_q
    clause = self._add_q(where_part, used_aliases)
  File "D:\Python27\lib\site-packages\django\db\models\sql\query.py", line 1234, in _add_q
    current_negated=current_negated)
  File "D:\Python27\lib\site-packages\django\db\models\sql\query.py", line 1075, in build_filter
    value = value()
TypeError: id() takes exactly one argument (0 given)
[2015-07-20 22:07:25,467] ERROR : Internal Server Error: /depotapp/api/cart/items
Traceback (most recent call last):
  File "D:\Python27\lib\site-packages\django\core\handlers\base.py", line 114, in get_response
    response = wrapped_callback(request, *callback_args, **callback_kwargs)
  File "D:\Python27\lib\site-packages\django\views\decorators\csrf.py", line 57, in wrapped_view
    return view_func(*args, **kwargs)
  File "D:\Python27\lib\site-packages\django\views\generic\base.py", line 69, in view
    return self.dispatch(request, *args, **kwargs)
  File "D:\Python27\lib\site-packages\rest_framework\views.py", line 456, in dispatch
    response = self.handle_exception(exc)
  File "D:\Python27\lib\site-packages\rest_framework\views.py", line 453, in dispatch
    response = handler(request, *args, **kwargs)
  File "D:\Python27\lib\site-packages\rest_framework\decorators.py", line 50, in handler
    return func(*args, **kwargs)
  File "D:\workspace\mysite\apps\depotapp\views.py", line 98, in cart_item_list
    lineitem=LineItem.objects.get(id=id)
  File "D:\Python27\lib\site-packages\django\db\models\manager.py", line 151, in get
    return self.get_queryset().get(*args, **kwargs)
  File "D:\Python27\lib\site-packages\django\db\models\query.py", line 298, in get
    clone = self.filter(*args, **kwargs)
  File "D:\Python27\lib\site-packages\django\db\models\query.py", line 590, in filter
    return self._filter_or_exclude(False, *args, **kwargs)
  File "D:\Python27\lib\site-packages\django\db\models\query.py", line 608, in _filter_or_exclude
    clone.query.add_q(Q(*args, **kwargs))
  File "D:\Python27\lib\site-packages\django\db\models\sql\query.py", line 1198, in add_q
    clause = self._add_q(where_part, used_aliases)
  File "D:\Python27\lib\site-packages\django\db\models\sql\query.py", line 1234, in _add_q
    current_negated=current_negated)
  File "D:\Python27\lib\site-packages\django\db\models\sql\query.py", line 1075, in build_filter
    value = value()
TypeError: id() takes exactly one argument (0 given)
[2015-07-20 22:07:34,528] ERROR : Internal Server Error: /depotapp/api/cart/items
Traceback (most recent call last):
  File "D:\Python27\lib\site-packages\django\core\handlers\base.py", line 114, in get_response
    response = wrapped_callback(request, *callback_args, **callback_kwargs)
  File "D:\Python27\lib\site-packages\django\views\decorators\csrf.py", line 57, in wrapped_view
    return view_func(*args, **kwargs)
  File "D:\Python27\lib\site-packages\django\views\generic\base.py", line 69, in view
    return self.dispatch(request, *args, **kwargs)
  File "D:\Python27\lib\site-packages\rest_framework\views.py", line 456, in dispatch
    response = self.handle_exception(exc)
  File "D:\Python27\lib\site-packages\rest_framework\views.py", line 453, in dispatch
    response = handler(request, *args, **kwargs)
  File "D:\Python27\lib\site-packages\rest_framework\decorators.py", line 50, in handler
    return func(*args, **kwargs)
  File "D:\workspace\mysite\apps\depotapp\views.py", line 98, in cart_item_list
    lineitem=LineItem.objects.get(id=id())
TypeError: id() takes exactly one argument (0 given)
[2015-07-20 22:07:36,769] ERROR : Internal Server Error: /depotapp/api/cart/items
Traceback (most recent call last):
  File "D:\Python27\lib\site-packages\django\core\handlers\base.py", line 114, in get_response
    response = wrapped_callback(request, *callback_args, **callback_kwargs)
  File "D:\Python27\lib\site-packages\django\views\decorators\csrf.py", line 57, in wrapped_view
    return view_func(*args, **kwargs)
  File "D:\Python27\lib\site-packages\django\views\generic\base.py", line 69, in view
    return self.dispatch(request, *args, **kwargs)
  File "D:\Python27\lib\site-packages\rest_framework\views.py", line 456, in dispatch
    response = self.handle_exception(exc)
  File "D:\Python27\lib\site-packages\rest_framework\views.py", line 453, in dispatch
    response = handler(request, *args, **kwargs)
  File "D:\Python27\lib\site-packages\rest_framework\decorators.py", line 50, in handler
    return func(*args, **kwargs)
  File "D:\workspace\mysite\apps\depotapp\views.py", line 98, in cart_item_list
    lineitem=LineItem.objects.get(id=id())
TypeError: id() takes exactly one argument (0 given)
[2015-07-20 22:07:45,792] ERROR : Internal Server Error: /depotapp/api/cart/items
Traceback (most recent call last):
  File "D:\Python27\lib\site-packages\django\core\handlers\base.py", line 114, in get_response
    response = wrapped_callback(request, *callback_args, **callback_kwargs)
  File "D:\Python27\lib\site-packages\django\views\decorators\csrf.py", line 57, in wrapped_view
    return view_func(*args, **kwargs)
  File "D:\Python27\lib\site-packages\django\views\generic\base.py", line 69, in view
    return self.dispatch(request, *args, **kwargs)
  File "D:\Python27\lib\site-packages\rest_framework\views.py", line 456, in dispatch
    response = self.handle_exception(exc)
  File "D:\Python27\lib\site-packages\rest_framework\views.py", line 453, in dispatch
    response = handler(request, *args, **kwargs)
  File "D:\Python27\lib\site-packages\rest_framework\decorators.py", line 50, in handler
    return func(*args, **kwargs)
  File "D:\workspace\mysite\apps\depotapp\views.py", line 98, in cart_item_list
    lineitem=LineItem.objects.get(id=1)
TypeError: id() takes exactly one argument (0 given)
[2015-07-20 22:08:08,167] ERROR : Internal Server Error: /depotapp/api/cart/items
Traceback (most recent call last):
  File "D:\Python27\lib\site-packages\django\core\handlers\base.py", line 114, in get_response
    response = wrapped_callback(request, *callback_args, **callback_kwargs)
  File "D:\Python27\lib\site-packages\django\views\decorators\csrf.py", line 57, in wrapped_view
    return view_func(*args, **kwargs)
  File "D:\Python27\lib\site-packages\django\views\generic\base.py", line 69, in view
    return self.dispatch(request, *args, **kwargs)
  File "D:\Python27\lib\site-packages\rest_framework\views.py", line 456, in dispatch
    response = self.handle_exception(exc)
  File "D:\Python27\lib\site-packages\rest_framework\views.py", line 453, in dispatch
    response = handler(request, *args, **kwargs)
  File "D:\Python27\lib\site-packages\rest_framework\decorators.py", line 50, in handler
    return func(*args, **kwargs)
  File "D:\workspace\mysite\apps\depotapp\views.py", line 102, in cart_item_list
    return JSONResponse(serializer.data)
  File "D:\Python27\lib\site-packages\rest_framework\serializers.py", line 622, in data
    ret = super(ListSerializer, self).data
  File "D:\Python27\lib\site-packages\rest_framework\serializers.py", line 217, in data
    self._data = self.to_representation(self.instance)
  File "D:\Python27\lib\site-packages\rest_framework\serializers.py", line 572, in to_representation
    self.child.to_representation(item) for item in iterable
TypeError: 'ModelBase' object is not iterable
[2015-07-20 22:08:10,298] ERROR : Internal Server Error: /depotapp/api/cart/items
Traceback (most recent call last):
  File "D:\Python27\lib\site-packages\django\core\handlers\base.py", line 114, in get_response
    response = wrapped_callback(request, *callback_args, **callback_kwargs)
  File "D:\Python27\lib\site-packages\django\views\decorators\csrf.py", line 57, in wrapped_view
    return view_func(*args, **kwargs)
  File "D:\Python27\lib\site-packages\django\views\generic\base.py", line 69, in view
    return self.dispatch(request, *args, **kwargs)
  File "D:\Python27\lib\site-packages\rest_framework\views.py", line 456, in dispatch
    response = self.handle_exception(exc)
  File "D:\Python27\lib\site-packages\rest_framework\views.py", line 453, in dispatch
    response = handler(request, *args, **kwargs)
  File "D:\Python27\lib\site-packages\rest_framework\decorators.py", line 50, in handler
    return func(*args, **kwargs)
  File "D:\workspace\mysite\apps\depotapp\views.py", line 102, in cart_item_list
    return JSONResponse(serializer.data)
  File "D:\Python27\lib\site-packages\rest_framework\serializers.py", line 622, in data
    ret = super(ListSerializer, self).data
  File "D:\Python27\lib\site-packages\rest_framework\serializers.py", line 217, in data
    self._data = self.to_representation(self.instance)
  File "D:\Python27\lib\site-packages\rest_framework\serializers.py", line 572, in to_representation
    self.child.to_representation(item) for item in iterable
TypeError: 'ModelBase' object is not iterable
[2015-07-20 22:08:30,888] ERROR : Internal Server Error: /depotapp/api/cart/items
Traceback (most recent call last):
  File "D:\Python27\lib\site-packages\django\core\handlers\base.py", line 114, in get_response
    response = wrapped_callback(request, *callback_args, **callback_kwargs)
  File "D:\Python27\lib\site-packages\django\views\decorators\csrf.py", line 57, in wrapped_view
    return view_func(*args, **kwargs)
  File "D:\Python27\lib\site-packages\django\views\generic\base.py", line 69, in view
    return self.dispatch(request, *args, **kwargs)
  File "D:\Python27\lib\site-packages\rest_framework\views.py", line 456, in dispatch
    response = self.handle_exception(exc)
  File "D:\Python27\lib\site-packages\rest_framework\views.py", line 453, in dispatch
    response = handler(request, *args, **kwargs)
  File "D:\Python27\lib\site-packages\rest_framework\decorators.py", line 50, in handler
    return func(*args, **kwargs)
  File "D:\workspace\mysite\apps\depotapp\views.py", line 102, in cart_item_list
    return JSONResponse(serializer.data)
  File "D:\Python27\lib\site-packages\rest_framework\serializers.py", line 622, in data
    ret = super(ListSerializer, self).data
  File "D:\Python27\lib\site-packages\rest_framework\serializers.py", line 217, in data
    self._data = self.to_representation(self.instance)
  File "D:\Python27\lib\site-packages\rest_framework\serializers.py", line 572, in to_representation
    self.child.to_representation(item) for item in iterable
TypeError: 'ModelBase' object is not iterable
[2015-07-20 22:08:31,832] ERROR : Internal Server Error: /depotapp/api/cart/items
Traceback (most recent call last):
  File "D:\Python27\lib\site-packages\django\core\handlers\base.py", line 114, in get_response
    response = wrapped_callback(request, *callback_args, **callback_kwargs)
  File "D:\Python27\lib\site-packages\django\views\decorators\csrf.py", line 57, in wrapped_view
    return view_func(*args, **kwargs)
  File "D:\Python27\lib\site-packages\django\views\generic\base.py", line 69, in view
    return self.dispatch(request, *args, **kwargs)
  File "D:\Python27\lib\site-packages\rest_framework\views.py", line 456, in dispatch
    response = self.handle_exception(exc)
  File "D:\Python27\lib\site-packages\rest_framework\views.py", line 453, in dispatch
    response = handler(request, *args, **kwargs)
  File "D:\Python27\lib\site-packages\rest_framework\decorators.py", line 50, in handler
    return func(*args, **kwargs)
  File "D:\workspace\mysite\apps\depotapp\views.py", line 102, in cart_item_list
    return JSONResponse(serializer.data)
  File "D:\Python27\lib\site-packages\rest_framework\serializers.py", line 622, in data
    ret = super(ListSerializer, self).data
  File "D:\Python27\lib\site-packages\rest_framework\serializers.py", line 217, in data
    self._data = self.to_representation(self.instance)
  File "D:\Python27\lib\site-packages\rest_framework\serializers.py", line 572, in to_representation
    self.child.to_representation(item) for item in iterable
TypeError: 'ModelBase' object is not iterable
[2015-07-20 22:15:37,135] ERROR : Internal Server Error: /depotapp/api/cart/items
Traceback (most recent call last):
  File "D:\Python27\lib\site-packages\django\core\handlers\base.py", line 90, in get_response
    response = middleware_method(request)
  File "D:\Python27\lib\site-packages\django\middleware\common.py", line 71, in process_request
    if (not urlresolvers.is_valid_path(request.path_info, urlconf) and
  File "D:\Python27\lib\site-packages\django\core\urlresolvers.py", line 596, in is_valid_path
    resolve(path, urlconf)
  File "D:\Python27\lib\site-packages\django\core\urlresolvers.py", line 476, in resolve
    return get_resolver(urlconf).resolve(path)
  File "D:\Python27\lib\site-packages\django\core\urlresolvers.py", line 337, in resolve
    for pattern in self.url_patterns:
  File "D:\Python27\lib\site-packages\django\core\urlresolvers.py", line 365, in url_patterns
    patterns = getattr(self.urlconf_module, "urlpatterns", self.urlconf_module)
  File "D:\Python27\lib\site-packages\django\core\urlresolvers.py", line 360, in urlconf_module
    self._urlconf_module = import_module(self.urlconf_name)
  File "D:\Python27\lib\site-packages\django\utils\importlib.py", line 40, in import_module
    __import__(name)
  File "D:\workspace\mysite\mysite\urls.py", line 24, in <module>
    url(r'^depotapp/',include('apps.depotapp.urls')),
  File "D:\Python27\lib\site-packages\django\conf\urls\__init__.py", line 26, in include
    urlconf_module = import_module(urlconf_module)
  File "D:\Python27\lib\site-packages\django\utils\importlib.py", line 40, in import_module
    __import__(name)
  File "D:\workspace\mysite\apps\depotapp\urls.py", line 4, in <module>
    import views
  File "D:\workspace\mysite\apps\depotapp\views.py", line 18, in <module>
    from serializers import LineItemSerializer
  File "D:\workspace\mysite\apps\depotapp\serializers.py", line 4, in <module>
    class LineItemSerializer(serializers.ModelSerializer):
  File "D:\workspace\mysite\apps\depotapp\serializers.py", line 5, in LineItemSerializer
    product = serializers.RelatedField(many=True)
  File "D:\Python27\lib\site-packages\rest_framework\relations.py", line 51, in __new__
    return cls.many_init(*args, **kwargs)
  File "D:\Python27\lib\site-packages\rest_framework\relations.py", line 71, in many_init
    list_kwargs = {'child_relation': cls(*args, **kwargs)}
  File "D:\Python27\lib\site-packages\rest_framework\relations.py", line 38, in __init__
    'Relational field must provide a `queryset` argument, '
AssertionError: Relational field must provide a `queryset` argument, or set read_only=`True`.
[2015-07-20 22:15:39,191] ERROR : Internal Server Error: /depotapp/api/cart/items
Traceback (most recent call last):
  File "D:\Python27\lib\site-packages\django\core\handlers\base.py", line 90, in get_response
    response = middleware_method(request)
  File "D:\Python27\lib\site-packages\django\middleware\common.py", line 71, in process_request
    if (not urlresolvers.is_valid_path(request.path_info, urlconf) and
  File "D:\Python27\lib\site-packages\django\core\urlresolvers.py", line 596, in is_valid_path
    resolve(path, urlconf)
  File "D:\Python27\lib\site-packages\django\core\urlresolvers.py", line 476, in resolve
    return get_resolver(urlconf).resolve(path)
  File "D:\Python27\lib\site-packages\django\core\urlresolvers.py", line 337, in resolve
    for pattern in self.url_patterns:
  File "D:\Python27\lib\site-packages\django\core\urlresolvers.py", line 365, in url_patterns
    patterns = getattr(self.urlconf_module, "urlpatterns", self.urlconf_module)
  File "D:\Python27\lib\site-packages\django\core\urlresolvers.py", line 360, in urlconf_module
    self._urlconf_module = import_module(self.urlconf_name)
  File "D:\Python27\lib\site-packages\django\utils\importlib.py", line 40, in import_module
    __import__(name)
  File "D:\workspace\mysite\mysite\urls.py", line 24, in <module>
    url(r'^depotapp/',include('apps.depotapp.urls')),
  File "D:\Python27\lib\site-packages\django\conf\urls\__init__.py", line 26, in include
    urlconf_module = import_module(urlconf_module)
  File "D:\Python27\lib\site-packages\django\utils\importlib.py", line 40, in import_module
    __import__(name)
  File "D:\workspace\mysite\apps\depotapp\urls.py", line 4, in <module>
    import views
  File "D:\workspace\mysite\apps\depotapp\views.py", line 18, in <module>
    from serializers import LineItemSerializer
  File "D:\workspace\mysite\apps\depotapp\serializers.py", line 4, in <module>
    class LineItemSerializer(serializers.ModelSerializer):
  File "D:\workspace\mysite\apps\depotapp\serializers.py", line 5, in LineItemSerializer
    product = serializers.RelatedField(many=True)
  File "D:\Python27\lib\site-packages\rest_framework\relations.py", line 51, in __new__
    return cls.many_init(*args, **kwargs)
  File "D:\Python27\lib\site-packages\rest_framework\relations.py", line 71, in many_init
    list_kwargs = {'child_relation': cls(*args, **kwargs)}
  File "D:\Python27\lib\site-packages\rest_framework\relations.py", line 38, in __init__
    'Relational field must provide a `queryset` argument, '
AssertionError: Relational field must provide a `queryset` argument, or set read_only=`True`.
[2015-07-20 22:15:40,529] ERROR : Internal Server Error: /depotapp/api/cart/items
Traceback (most recent call last):
  File "D:\Python27\lib\site-packages\django\core\handlers\base.py", line 90, in get_response
    response = middleware_method(request)
  File "D:\Python27\lib\site-packages\django\middleware\common.py", line 71, in process_request
    if (not urlresolvers.is_valid_path(request.path_info, urlconf) and
  File "D:\Python27\lib\site-packages\django\core\urlresolvers.py", line 596, in is_valid_path
    resolve(path, urlconf)
  File "D:\Python27\lib\site-packages\django\core\urlresolvers.py", line 476, in resolve
    return get_resolver(urlconf).resolve(path)
  File "D:\Python27\lib\site-packages\django\core\urlresolvers.py", line 337, in resolve
    for pattern in self.url_patterns:
  File "D:\Python27\lib\site-packages\django\core\urlresolvers.py", line 365, in url_patterns
    patterns = getattr(self.urlconf_module, "urlpatterns", self.urlconf_module)
  File "D:\Python27\lib\site-packages\django\core\urlresolvers.py", line 360, in urlconf_module
    self._urlconf_module = import_module(self.urlconf_name)
  File "D:\Python27\lib\site-packages\django\utils\importlib.py", line 40, in import_module
    __import__(name)
  File "D:\workspace\mysite\mysite\urls.py", line 24, in <module>
    url(r'^depotapp/',include('apps.depotapp.urls')),
  File "D:\Python27\lib\site-packages\django\conf\urls\__init__.py", line 26, in include
    urlconf_module = import_module(urlconf_module)
  File "D:\Python27\lib\site-packages\django\utils\importlib.py", line 40, in import_module
    __import__(name)
  File "D:\workspace\mysite\apps\depotapp\urls.py", line 4, in <module>
    import views
  File "D:\workspace\mysite\apps\depotapp\views.py", line 18, in <module>
    from serializers import LineItemSerializer
  File "D:\workspace\mysite\apps\depotapp\serializers.py", line 4, in <module>
    class LineItemSerializer(serializers.ModelSerializer):
  File "D:\workspace\mysite\apps\depotapp\serializers.py", line 5, in LineItemSerializer
    product = serializers.RelatedField(many=True)
  File "D:\Python27\lib\site-packages\rest_framework\relations.py", line 51, in __new__
    return cls.many_init(*args, **kwargs)
  File "D:\Python27\lib\site-packages\rest_framework\relations.py", line 71, in many_init
    list_kwargs = {'child_relation': cls(*args, **kwargs)}
  File "D:\Python27\lib\site-packages\rest_framework\relations.py", line 38, in __init__
    'Relational field must provide a `queryset` argument, '
AssertionError: Relational field must provide a `queryset` argument, or set read_only=`True`.
[2015-07-20 22:15:54,085] ERROR : Internal Server Error: /depotapp/api/cart/items
Traceback (most recent call last):
  File "D:\Python27\lib\site-packages\django\core\handlers\base.py", line 114, in get_response
    response = wrapped_callback(request, *callback_args, **callback_kwargs)
  File "D:\Python27\lib\site-packages\django\views\decorators\csrf.py", line 57, in wrapped_view
    return view_func(*args, **kwargs)
  File "D:\Python27\lib\site-packages\django\views\generic\base.py", line 69, in view
    return self.dispatch(request, *args, **kwargs)
  File "D:\Python27\lib\site-packages\rest_framework\views.py", line 456, in dispatch
    response = self.handle_exception(exc)
  File "D:\Python27\lib\site-packages\rest_framework\views.py", line 453, in dispatch
    response = handler(request, *args, **kwargs)
  File "D:\Python27\lib\site-packages\rest_framework\decorators.py", line 50, in handler
    return func(*args, **kwargs)
  File "D:\workspace\mysite\apps\depotapp\views.py", line 102, in cart_item_list
    return JSONResponse(serializer.data)
  File "D:\Python27\lib\site-packages\rest_framework\serializers.py", line 622, in data
    ret = super(ListSerializer, self).data
  File "D:\Python27\lib\site-packages\rest_framework\serializers.py", line 217, in data
    self._data = self.to_representation(self.instance)
  File "D:\Python27\lib\site-packages\rest_framework\serializers.py", line 572, in to_representation
    self.child.to_representation(item) for item in iterable
TypeError: 'ModelBase' object is not iterable
